<?xml version="1.0"?>
<robot xmlns:xacro="http://www.ros.org/wiki/xacro">

    <!-- <link name="base_footprint" /> -->

    <link name="arm_base_link">
        <visual>
            <geometry>
                <box size="0.1 0.1 0.02" />
            </geometry>
            <origin xyz="0 0 0" rpy="0 0 0" />
            <material name="orange" />
        </visual>
        <collision>
            <geometry>
                <box size="0.1 0.1 0.02" />
            </geometry>
            <origin xyz="0 0 0" rpy="0 0 0" />
        </collision>
        <xacro:box_inertia m="0.5" l="0.1" w="0.1" h="0.02" xyz="0 0 0.01" rpy="0 0 0" />
    </link>

    <link name="forearm_link">
        <visual>
            <geometry>
                <cylinder radius="0.02" length="0.3" />
            </geometry>
            <origin xyz="0 0 0.15" rpy="0 0 0" />
            <material name="yellow" />
        </visual>
        <collision>
            <geometry>
                <cylinder radius="0.02" length="0.3" />
            </geometry>
            <origin xyz="0 0 0.15" rpy="0 0 0" />
        </collision>
        <xacro:cylinder_inertia m="0.3" r="0.02" h="0.3" xyz="0 0 0.15" rpy="0 0 0" />
    </link>

    <link name="hand_link">
        <visual>
            <geometry>
                <cylinder radius="0.02" length="0.3" />
            </geometry>
            <origin xyz="0 0 0.15" rpy="0 0 0" />
            <material name="orange" />
        </visual>
        <collision>
            <geometry>
                <cylinder radius="0.02" length="0.3" />
            </geometry>
            <origin xyz="0 0 0.15" rpy="0 0 0" />
        </collision>
        <xacro:cylinder_inertia m="0.3" r="0.02" h="0.3" xyz="0 0 0.15" rpy="0 0 0" />
    </link>


    <!-- <joint name="base_joint" type="fixed">
        <parent link="base_footprint" />
        <child link="arm_base_link" />
        <origin xyz="0 0 0.01" rpy="0 0 0" />
    </joint> -->

    <joint name="base_forearm_joint" type="revolute">
        <parent link="arm_base_link" />
        <child link="forearm_link" />
        <origin xyz="0 0 0.01" rpy="0 0 0" />
        <limit lower="0" upper="1.57" effort="100" velocity="100" />
        <axis xyz="0 1 0" />
        <dynamics friction="0.05" damping="0.1" />
    </joint>

    <joint name="forearm_hand_joint" type="revolute">
        <parent link="forearm_link" />
        <child link="hand_link" />
        <origin xyz="0 0 0.3" rpy="0 0 0" />
        <limit lower="0" upper="1.57" effort="100" velocity="100" />
        <axis xyz="0 1 0" />
        <dynamics friction="0.05" damping="0.1" />
    </joint>


</robot>